Workbook
Name Pay_Mode: '⚙️ SETTINGS'!$I$5:$I$10
Name Plan_Duration_Lookup: '⚙️ SETTINGS'!$B$19:$C$22
Name Plan_Type: '⚙️ SETTINGS'!$E$5:$E$8
Name Priority: '⚙️ SETTINGS'!$H$5:$H$7
Name Progress: '⚙️ SETTINGS'!$B$5:$B$9
Name Source: '⚙️ SETTINGS'!$D$5:$D$12
Name Status: '⚙️ SETTINGS'!$C$5:$C$7
Name Task_Status: '⚙️ SETTINGS'!$G$5:$G$9
Name Tier: '⚙️ SETTINGS'!$F$5:$F$9

Sheet ⚙️ SETTINGS
A1: ⚙️ SETTINGS — All Dropdown Lists Managed Here
A2: Edit any list below → Save → All dropdowns across all sheets update automatically
B4: Progress | C4: Status | D4: Source | E4: Plan Type | F4: Tier | G4: Task Status | H4: Priority | I4: Pay Mode
B5: Very Good | C5: Active | D5: BNI | E5: 1 Month Plan | F5: 5 ⭐⭐⭐⭐⭐ | G5: Open | H5: High | I5: GPay
B6: Good | C6: Hold | D6: Instagram | E6: 3 Month Plan | F6: 4 ⭐⭐⭐⭐ | G6: In Progress | H6: Medium | I6: Cash
B7: Neutral | C7: Inactive | D7: Facebook | E7: 6 Month Plan | F7: 3 ⭐⭐⭐ | G7: Done ✅ | H7: Low | I7: Online Transfer
B8: Poor | D8: Referral - Existing Client | E8: 1 Year Plan | F8: 2 ⭐⭐ | G8: Carried Forward ➡ | I8: Cheque
B9: Very Poor | D9: Friend / Family | F9: 1 ⭐ | G9: Overdue 🔴 | I9: UPI
D10: Walk-in | I10: NEFT
D11: Online / Website
D12: Corporate / Company
B15: 💡 HOW TO EDIT: Add or change any value in the lists above → Save file → All dropdowns update automatically across all sheets | Do NOT delete column headers in row 4
B18: PLAN DURATION LOOKUP (do not edit)
B19: 1 Month Plan | C19: 30
B20: 3 Month Plan | C20: 90
B21: 6 Month Plan | C21: 180
B22: 1 Year Plan | C22: 365

Sheet 📋 MASTER
A1: 🌿 FITNESS VITNESS — CLIENT PERFORMANCE MASTER DASHBOARD
A2: All data auto-synced from client sheets | Click any client name to open full profile | Update KEY FIELDS on client sheet only
B4: =COUNTIF(E6:E15,"Active") -> 0 | D4: =COUNTIF(E6:E15,"Hold") -> 0 | F4: =COUNTIF(F6:F15,"Poor")+COUNTIF(F6:F15,"Very Poor") -> 0 | H4: =COUNTIF(I6:I15,"*OVERDUE*") -> 0 | J4: =COUNTIF(K6:K15,"<14") -> 0 | L4: =COUNTIF(M6:M15,"5*") -> 2
B5: Active Clients | D5: On Hold | F5: Need Attention | H5: Overdue Follow-ups | J5: Plans Expiring Soon | L5: 5-Star Clients ⭐
A7: ID | B7: CLIENT NAME | C7: STATUS | D7: PROGRESS | E7: LAST CONSULT (auto) | F7: NEXT DUE | G7: DAYS REMAINING | H7: FOLLOW-UP PRIORITY | I7: PLAN EXPIRY | J7: DAYS TO EXPIRY | K7: PLAN TYPE | L7: SOURCE | M7: TIER | N7: ⚠️ RISK
A8: FV-001 | B8: Priya Sharma | C8: ='FV-001'!E6 -> Active | D8: ='FV-001'!D6 -> Good | E8: ='FV-001'!C6 -> 46082 | F8: =IFERROR(E8+'FV-001'!H6,"") -> 46096 | G8: =IFERROR(F8-TODAY(),"") -> -53 | H8: =IFERROR(IF(G8<0,"🔴 OVERDUE",IF(G8<=5,"🟡 Due Soon","🟢 On Track")),"—") -> 🔴 OVERDUE | I8: =IFERROR('FV-001'!G6,"") -> Check Plan Type | J8: =IFERROR(I8-TODAY(),"") | K8: ='FV-001'!F6 -> 3 Month Plan | L8: ='FV-001'!J6 -> BNI | M8: ='FV-001'!I6 -> 5 ⭐⭐⭐⭐⭐ | N8: =IFERROR(IF(AND(OR(D8="Poor",D8="Very Poor"),G8<0),"⚠️ HIGH RISK","✅ OK"),"—") -> ✅ OK
A9: FV-002 | B9: Rahul Mehta | C9: ='FV-002'!E6 -> Active | D9: ='FV-002'!D6 -> Very Good | E9: ='FV-002'!C6 -> 46096 | F9: =IFERROR(E9+'FV-002'!H6,"") -> 46117 | G9: =IFERROR(F9-TODAY(),"") -> -32 | H9: =IFERROR(IF(G9<0,"🔴 OVERDUE",IF(G9<=5,"🟡 Due Soon","🟢 On Track")),"—") -> 🔴 OVERDUE | I9: =IFERROR('FV-002'!G6,"") -> Check Plan Type | J9: =IFERROR(I9-TODAY(),"") | K9: ='FV-002'!F6 -> 6 Month Plan | L9: ='FV-002'!J6 -> Instagram | M9: ='FV-002'!I6 -> 4 ⭐⭐⭐⭐ | N9: =IFERROR(IF(AND(OR(D9="Poor",D9="Very Poor"),G9<0),"⚠️ HIGH RISK","✅ OK"),"—") -> ✅ OK
A10: FV-003 | B10: Sneha Patel | C10: ='FV-003'!E6 -> Active | D10: ='FV-003'!D6 -> Poor | E10: ='FV-003'!C6 -> 46063 | F10: =IFERROR(E10+'FV-003'!H6,"") -> 46070 | G10: =IFERROR(F10-TODAY(),"") -> -79 | H10: =IFERROR(IF(G10<0,"🔴 OVERDUE",IF(G10<=5,"🟡 Due Soon","🟢 On Track")),"—") -> 🔴 OVERDUE | I10: =IFERROR('FV-003'!G6,"") -> Check Plan Type | J10: =IFERROR(I10-TODAY(),"") | K10: ='FV-003'!F6 -> 3 Month Plan | L10: ='FV-003'!J6 -> Referral - Existing Client | M10: ='FV-003'!I6 -> 3 ⭐⭐⭐ | N10: =IFERROR(IF(AND(OR(D10="Poor",D10="Very Poor"),G10<0),"⚠️ HIGH RISK","✅ OK"),"—") -> ⚠️ HIGH RISK
A11: FV-004 | B11: Amit Verma | C11: ='FV-004'!E6 -> Hold | D11: ='FV-004'!D6 -> Neutral | E11: ='FV-004'!C6 -> 46073 | F11: =IFERROR(E11+'FV-004'!H6,"") -> 46103 | G11: =IFERROR(F11-TODAY(),"") -> -46 | H11: =IFERROR(IF(G11<0,"🔴 OVERDUE",IF(G11<=5,"🟡 Due Soon","🟢 On Track")),"—") -> 🔴 OVERDUE | I11: =IFERROR('FV-004'!G6,"") -> Check Plan Type | J11: =IFERROR(I11-TODAY(),"") | K11: ='FV-004'!F6 -> 1 Month Plan | L11: ='FV-004'!J6 -> Online / Website | M11: ='FV-004'!I6 -> 2 ⭐⭐ | N11: =IFERROR(IF(AND(OR(D11="Poor",D11="Very Poor"),G11<0),"⚠️ HIGH RISK","✅ OK"),"—") -> ✅ OK
A12: FV-005 | B12: Kavita Joshi | C12: ='FV-005'!E6 -> Active | D12: ='FV-005'!D6 -> Very Poor | E12: ='FV-005'!C6 -> 46052 | F12: =IFERROR(E12+'FV-005'!H6,"") -> 46066 | G12: =IFERROR(F12-TODAY(),"") -> -83 | H12: =IFERROR(IF(G12<0,"🔴 OVERDUE",IF(G12<=5,"🟡 Due Soon","🟢 On Track")),"—") -> 🔴 OVERDUE | I12: =IFERROR('FV-005'!G6,"") -> Check Plan Type | J12: =IFERROR(I12-TODAY(),"") | K12: ='FV-005'!F6 -> 6 Month Plan | L12: ='FV-005'!J6 -> BNI | M12: ='FV-005'!I6 -> 5 ⭐⭐⭐⭐⭐ | N12: =IFERROR(IF(AND(OR(D12="Poor",D12="Very Poor"),G12<0),"⚠️ HIGH RISK","✅ OK"),"—") -> ⚠️ HIGH RISK
A13: FV-006 | B13: Rohit Desai | C13: ='FV-006'!E6 -> Active | D13: ='FV-006'!D6 -> Good | E13: ='FV-006'!C6 -> 46091 | F13: =IFERROR(E13+'FV-006'!H6,"") -> 46112 | G13: =IFERROR(F13-TODAY(),"") -> -37 | H13: =IFERROR(IF(G13<0,"🔴 OVERDUE",IF(G13<=5,"🟡 Due Soon","🟢 On Track")),"—") -> 🔴 OVERDUE | I13: =IFERROR('FV-006'!G6,"") -> Check Plan Type | J13: =IFERROR(I13-TODAY(),"") | K13: ='FV-006'!F6 -> 3 Month Plan | L13: ='FV-006'!J6 -> Referral - Existing Client | M13: ='FV-006'!I6 -> 3 ⭐⭐⭐ | N13: =IFERROR(IF(AND(OR(D13="Poor",D13="Very Poor"),G13<0),"⚠️ HIGH RISK","✅ OK"),"—") -> ✅ OK
A14: FV-007 | B14: Meena Kulkarni | C14: ='FV-007'!E6 -> Active | D14: ='FV-007'!D6 -> Poor | E14: ='FV-007'!C6 -> 46078 | F14: =IFERROR(E14+'FV-007'!H6,"") -> 46085 | G14: =IFERROR(F14-TODAY(),"") -> -64 | H14: =IFERROR(IF(G14<0,"🔴 OVERDUE",IF(G14<=5,"🟡 Due Soon","🟢 On Track")),"—") -> 🔴 OVERDUE | I14: =IFERROR('FV-007'!G6,"") -> Check Plan Type | J14: =IFERROR(I14-TODAY(),"") | K14: ='FV-007'!F6 -> 6 Month Plan | L14: ='FV-007'!J6 -> Referral - Existing Client | M14: ='FV-007'!I6 -> 2 ⭐⭐ | N14: =IFERROR(IF(AND(OR(D14="Poor",D14="Very Poor"),G14<0),"⚠️ HIGH RISK","✅ OK"),"—") -> ⚠️ HIGH RISK
A15: FV-008 | B15: Suresh Nair | C15: ='FV-008'!E6 -> Hold | D15: ='FV-008'!D6 -> Good | E15: ='FV-008'!C6 -> 46099 | F15: =IFERROR(E15+'FV-008'!H6,"") -> 46129 | G15: =IFERROR(F15-TODAY(),"") -> -20 | H15: =IFERROR(IF(G15<0,"🔴 OVERDUE",IF(G15<=5,"🟡 Due Soon","🟢 On Track")),"—") -> 🔴 OVERDUE | I15: =IFERROR('FV-008'!G6,"") -> Check Plan Type | J15: =IFERROR(I15-TODAY(),"") | K15: ='FV-008'!F6 -> 1 Month Plan | L15: ='FV-008'!J6 -> Referral - Existing Client | M15: ='FV-008'!I6 -> 3 ⭐⭐⭐ | N15: =IFERROR(IF(AND(OR(D15="Poor",D15="Very Poor"),G15<0),"⚠️ HIGH RISK","✅ OK"),"—") -> ✅ OK
A16: FV-009 | B16: Anita Singh | C16: ='FV-009'!E6 -> Active | D16: ='FV-009'!D6 -> Very Good | E16: ='FV-009'!C6 -> 46101 | F16: =IFERROR(E16+'FV-009'!H6,"") -> 46115 | G16: =IFERROR(F16-TODAY(),"") -> -34 | H16: =IFERROR(IF(G16<0,"🔴 OVERDUE",IF(G16<=5,"🟡 Due Soon","🟢 On Track")),"—") -> 🔴 OVERDUE | I16: =IFERROR('FV-009'!G6,"") -> Check Plan Type | J16: =IFERROR(I16-TODAY(),"") | K16: ='FV-009'!F6 -> 3 Month Plan | L16: ='FV-009'!J6 -> Referral - Existing Client | M16: ='FV-009'!I6 -> 4 ⭐⭐⭐⭐ | N16: =IFERROR(IF(AND(OR(D16="Poor",D16="Very Poor"),G16<0),"⚠️ HIGH RISK","✅ OK"),"—") -> ✅ OK
A17: FV-010 | B17: Deepak Chauhan | C17: ='FV-010'!E6 -> Active | D17: ='FV-010'!D6 -> Neutral | E17: ='FV-010'!C6 -> 46086 | F17: =IFERROR(E17+'FV-010'!H6,"") -> 46107 | G17: =IFERROR(F17-TODAY(),"") -> -42 | H17: =IFERROR(IF(G17<0,"🔴 OVERDUE",IF(G17<=5,"🟡 Due Soon","🟢 On Track")),"—") -> 🔴 OVERDUE | I17: =IFERROR('FV-010'!G6,"") -> Check Plan Type | J17: =IFERROR(I17-TODAY(),"") | K17: ='FV-010'!F6 -> 6 Month Plan | L17: ='FV-010'!J6 -> Referral - Existing Client | M17: ='FV-010'!I6 -> 2 ⭐⭐ | N17: =IFERROR(IF(AND(OR(D17="Poor",D17="Very Poor"),G17<0),"⚠️ HIGH RISK","✅ OK"),"—") -> ✅ OK
A20: 💡 ⭐⭐⭐⭐⭐ 5-Star clients highlighted in gold — prioritise relationship building | 🟠 HOLD = client on break, still in membership | All data flows from client sheets automatically

Sheet 📊 ANALYTICS
A1: 📊 BUSINESS ANALYTICS — Insights at a Glance
A2: Where clients come from, who your top referrers are, and where to focus your energy
B4: 📍 SOURCE BREAKDOWN — Where are your clients coming from?
B5: Source | C5: Clients | D5: % of Total | E5: Avg Tier | F5: Action
B6: BNI | C6: 2 | D6: 20% | E6: 5.0 ⭐⭐⭐⭐⭐ | F6: 🔥 High value — attend more meetings
B7: Instagram | C7: 1 | D7: 10% | E7: 4.0 ⭐⭐⭐⭐ | F7: 📱 Review content strategy
B8: Facebook | C8: — | D8: 0% | E8: —
B9: Referral - Existing Client | C9: 6 | D9: 60% | E9: 2.8 ⭐⭐⭐ | F9: ⭐ Best channel — reward referrers
B10: Friend / Family | C10: — | D10: 0% | E10: —
B11: Walk-in | C11: — | D11: 0% | E11: —
B12: Online / Website | C12: 1 | D12: 10% | E12: 2.0 ⭐⭐ | F12: 🌐 Optimise SEO
B13: Corporate / Company | C13: — | D13: 0% | E13: —
B14: 🟢 Top source highlighted | Focus on sources with highest average tier — they bring most committed clients
B17: ⭐ TIER DISTRIBUTION — Your client value overview
B18: Tier | C18: Clients | D18: % of Total | E18: Your Action
B19: ⭐⭐⭐⭐⭐ | C19: 2 | D19: 20% | E19: 🏆 Call weekly — maximum relationship investment
B20: ⭐⭐⭐⭐☆ | C20: 2 | D20: 20% | E20: 🌟 Monthly personal call — strong nurturing
B21: ⭐⭐⭐☆☆ | C21: 3 | D21: 30% | E21: 💪 Standard follow-up — routine service
B22: ⭐⭐☆☆☆ | C22: 3 | D22: 30% | E22: 🌱 Basic service — routine protocol
B23: ⭐☆☆☆☆ | C23: — | D23: 0% | E23: 👋 Minimum touch — standard only
B25: 🤝 TOP REFERRERS — Who is growing your business?
B26: Client (ID) | C26: Tier | D26: Referrals | E26: Source They Came From | F26: Your Action
B27: Kavita Joshi (FV-005) | C27: 5 ⭐⭐⭐⭐⭐ | D27: 3 | E27: BNI | F27: 🔥 Call this week — key growth driver
B28: Priya Sharma (FV-001) | C28: 5 ⭐⭐⭐⭐⭐ | D28: 2 | E28: BNI | F28: 📞 Personal call this month — nurture
B29: Rahul Mehta (FV-002) | C29: 4 ⭐⭐⭐⭐ | D29: 1 | E29: Instagram | F29: 📞 Personal call this month — nurture
B35: 💰 FINANCIAL SNAPSHOT — (Full details in Business Tracker)
B36: Month | C36: Received (₹) | D36: Pending (₹) | E36: Cost (₹) | F36: Profit (₹)
B37: January | C37: 8700 | D37: 0 | E37: 1800 | F37: 6900
B38: February | C38: 30100 | D38: 6000 | E38: 1000 | F38: 29100
B39: March | C39: 24300 | D39: 3000 | E39: 2700 | F39: 21600
B40: → For complete monthly & yearly breakdown, open the 💼 Business Tracker sheet

Sheet 💼 BUSINESS
A1: 💼 BUSINESS TRACKER — All Transactions, Revenue & Summaries
A2: Enter transactions here with Client ID → Payment History on client sheet updates automatically
B4: =IFERROR(SUM(H11:H500),0) -> 76382 | D4: =IFERROR(SUM(I11:I500),0) -> 9000 | F4: =IFERROR(SUM(K11:K500),0) -> 70850 | H4: =IFERROR(COUNTA(C11:C500),0) -> 18 | J4: =IFERROR(SUMIF(E11:E500,"Membership",H11:H500),0) -> 68000 | L4: =IFERROR(SUMIF(E11:E500,"Supplement",H11:H500),0) -> 8350
B5: Total Received | D5: Total Pending | F5: Total Profit | H5: Transactions | J5: Membership Rev | L5: Supplement Rev
B7: 📋 TRANSACTION LOG — Tag every transaction with Client ID for auto-sync to client sheets
B8: ⚡ IMPORTANT: Always fill Client ID (col A) correctly — this is what links to the client's payment history automatically
B9: Use Data → Filter to sort by client, date, or type | Profit = Received - Cost (auto-calculated)
A10: Client ID | B10: Date | C10: Client Name | D10: Product / Plan | E10: Type | F10: MRP (₹) | G10: Rate (₹) | H10: Received (₹) | I10: Pending (₹) | J10: Cost (₹) | K10: Profit (₹) | L10: Mode
A11: FV-001 | B11: 46037 | C11: Priya Sharma | D11: 3 Month Plan | E11: Membership | G11: 6000 | H11: 6000 | I11: 0 | K11: =IFERROR(H11-J11,"") -> 6000 | L11: GPay
A12: FV-001 | B12: 46037 | C12: Priya Sharma | D12: HydroPure Whey Protein | E12: Supplement | F12: 2999 | G12: 2700 | H12: 2700 | I12: 0 | J12: 1800 | K12: =IFERROR(H12-J12,"") -> 900 | L12: Cash
A13: FV-002 | B13: 46042 | C13: Rahul Mehta | D13: 6 Month Plan | E13: Membership | G13: 12000 | H13: 12000 | I13: 0 | K13: =IFERROR(H13-J13,"") -> 12000 | L13: Online Transfer
A14: FV-003 | B14: 46054 | C14: Sneha Patel | D14: 3 Month Plan | E14: Membership | G14: 6000 | H14: 4000 | I14: 2000 | K14: =IFERROR(H14-J14,"") -> 4000 | L14: Cash
A15: FV-003 | B15: 46054 | C15: Sneha Patel | D15: PharmGrade Multivitamin | E15: Supplement | F15: 1800 | G15: 1600 | H15: 1600 | I15: 0 | J15: 1000 | K15: =IFERROR(H15-J15,"") -> 600 | L15: Cash
A16: FV-004 | B16: 46058 | C16: Amit Verma | D16: 1 Month Plan | E16: Membership | G16: 2500 | H16: 2500 | I16: 0 | K16: =IFERROR(H16-J16,"") -> 2500 | L16: GPay
A17: FV-005 | B17: 46063 | C17: Kavita Joshi | D17: 6 Month Plan | E17: Membership | G17: 12000 | H17: 8000 | I17: 4000 | K17: =IFERROR(H17-J17,"") -> 8000 | L17: Online Transfer
A18: FV-006 | B18: 46068 | C18: Rohit Desai | D18: 3 Month Plan | E18: Membership | G18: 6000 | H18: 6000 | I18: 0 | K18: =IFERROR(H18-J18,"") -> 6000 | L18: Cash
A19: FV-007 | B19: 46073 | C19: Meena Kulkarni | D19: 6 Month Plan | E19: Membership | G19: 12000 | H19: 12000 | I19: 0 | K19: =IFERROR(H19-J19,"") -> 12000 | L19: Online Transfer
A20: FV-008 | B20: 46082 | C20: Suresh Nair | D20: 1 Month Plan | E20: Membership | G20: 2500 | H20: 2500 | I20: 0 | K20: =IFERROR(H20-J20,"") -> 2500 | L20: GPay
A21: FV-009 | B21: 46086 | C21: Anita Singh | D21: 3 Month Plan | E21: Membership | G21: 6000 | H21: 6000 | I21: 0 | K21: =IFERROR(H21-J21,"") -> 6000 | L21: Online Transfer
A22: FV-010 | B22: 46091 | C22: Deepak Chauhan | D22: 6 Month Plan | E22: Membership | G22: 12000 | H22: 9000 | I22: 3000 | K22: =IFERROR(H22-J22,"") -> 9000 | L22: Cash
A23: FV-001 | B23: 46093 | C23: Priya Sharma | D23: Omega-3 Fish Oil | E23: Supplement | F23: 1499 | G23: 1350 | H23: 1350 | I23: 0 | J23: 900 | K23: =IFERROR(H23-J23,"") -> 450 | L23: GPay
A24: FV-002 | B24: 46096 | C24: Rahul Mehta | D24: HydroPure Vanilla Protein | E24: Supplement | F24: 2999 | G24: 2700 | H24: 2700 | I24: 0 | J24: 1800 | K24: =IFERROR(H24-J24,"") -> 900 | L24: Cash
K25: =IFERROR(H25-J25,"") -> 0
K26: =IFERROR(H26-J26,"") -> 0
K27: =IFERROR(H27-J27,"") -> 0
K28: =IFERROR(H28-J28,"") -> 0
K29: =IFERROR(H29-J29,"") -> 0
K30: =IFERROR(H30-J30,"") -> 0
K31: =IFERROR(H31-J31,"") -> 0
K32: =IFERROR(H32-J32,"") -> 0
K33: =IFERROR(H33-J33,"") -> 0
K34: =IFERROR(H34-J34,"") -> 0
K35: =IFERROR(H35-J35,"") -> 0
K36: =IFERROR(H36-J36,"") -> 0
... K54: =IFERROR(H54-J54,"") -> 0
B57: 📅 MONTHLY SUMMARY 2026 — Auto-calculated from transaction log
A58: Month | B58: Received (₹) | C58: Pending (₹) | D58: Cost (₹) | E58: Profit (₹) | F58: Membership (₹) | G58: Supplement (₹) | H58: # Transactions
A59: January | B59: 8700 | D59: 1800 | E59: 6900 | F59: 6000 | G59: 2700 | H59: 3
A60: February | B60: 30100 | C60: 6000 | D60: 1000 | E60: 29100 | F60: 26500 | G60: 3600 | H60: 7
A61: March | B61: 24300 | C61: 3000 | D61: 2700 | E61: 21600 | F61: 21000 | G61: 3300 | H61: 6
...

Sheet FV-001
A1: 🌿 FITNESS VITNESS | PRIYA SHARMA | FV-001
A2: ⬅ Back to Master | Yellow = KEY FIELDS — update here, Master syncs automatically
B4: 🔗 KEY FIELDS — These automatically update the Master Sheet
B5: Client ID | C5: Last Consultation | D5: Progress | E5: Status | F5: Plan Type | G5: Plan Expiry | H5: Follow-up Freq (days) | I5: Client Tier | J5: Source
B6: FV-001 | C6: 46082 | D6: Good | E6: Active | F6: 3 Month Plan | G6: =IFERROR(G6+VLOOKUP(F6,Plan_Duration_Lookup,2,0),"Check Plan Type") -> Check Plan Type | H6: 14 | I6: 5 ⭐⭐⭐⭐⭐ | J6: BNI
B7: ⬆ Update yellow cells after each consultation. Plan Expiry calculates automatically from Plan Type + Start Date.
B9: 📌 PERSONAL DETAILS
B10: Full Name | C10: Priya Sharma | E10: Age | F10: 34
B11: Client ID | C11: FV-001 | E11: Phone | F11: 9876543210
B12: City | C12: Vapi | E12: Email
B13: Address | E13: Occupation
B14: Referred By | C14: — | E14: Emergency Contact
B16: 🎯 PLAN & GOALS
B17: Health Goal | C17: Weight Loss | E17: Plan Type | F17: 3 Month Plan
B18: Plan Start Date | C18: 46037 | E18: Plan Duration | F18: 90 days (auto)
B19: Plan Expiry | C19: =IFERROR(C18+VLOOKUP(F6,Plan_Duration_Lookup,2,0),"—") -> 46127 | E19: Days Remaining | F19: =IFERROR(C19-TODAY(),"—") -> -22
B20: Medical Conditions | E20: Allergies / Avoid
B21: Activity Level | E21: Current Medications
B23: 📏 BODY STATS & BMI
B24: Height (cm) | C24: 162 | E24: Start Weight (kg) | F24: 78
B25: Current Weight (kg) | C25: 74.2 | E25: Target Weight (kg)
B26: BMI | C26: =IFERROR(ROUND(C25/((C24/100)^2),1),"—") -> 28.3 | E26: BMI Category | F26: =IFERROR(IF(C26<18.5,"⬇ Underweight",IF(C26<25,"✅ Normal",IF(C26<30,"⚠️ Overweight","🔴 Obese"))),"—") -> ⚠️ Overweight
B27: Weight Change | C27: =IFERROR(C24-C25,"—") -> 87.8 | E27: % to Goal | F27: =IFERROR(TEXT((C24-C25)/(C24-F25),"0%"),"—") -> 54%
B29: 🤝 REFERRAL DETAILS
B30: Total Referrals Given | C30: 2 | E30: Client Tier | F30: 5 ⭐⭐⭐⭐⭐
B31: # | C31: Client Name Referred | D31: Client ID | E31: Date Referred | F31: Notes
B32: 1 | C32: Rohit Desai
B33: 2 | C33: Suresh Nair
B34: 3
B35: 4
B36: 5
B38: ✅ TASK ENGINE — Create, track & carry forward tasks
B39: Task Description | C39: Due Date | D39: Priority | E39: Status | F39: Period | G39: Completed On | H39: Notes
B40: Diet Review Call | C40: 46096 | D40: High | E40: Open | F40: This Week | H40: Review weight & adjust plan
B41: Send Updated Meal Plan | C41: 46107 | D41: High | E41: Open | F41: This Week | H41: Based on last consultation
B42: Check Supplement Stock | C42: 46110 | D42: Medium | E42: Open | F42: Next Week | H42: Ask if protein running low
B43: Monthly Progress Review | C43: 46112 | D43: High | E43: Open | F43: This Month | H43: Full BMI + energy check
B44: Payment / Renewal Reminder | C44: 46120 | D44: Medium | E44: Open | F44: Before Expiry | H44: Remind before plan expires
B45: Initial Consultation | C45: 46037 | D45: High | E45: Done ✅ | F45: Week 1 | G45: 2026-01-15 | H45: Onboarding complete
B46: First Diet Plan Delivery | C46: 46039 | D46: High | E46: Done ✅ | F46: Week 1 | G46: 2026-01-17 | H46: Sent via WhatsApp
...

Sheet FV-002
A1: 🌿 FITNESS VITNESS | RAHUL MEHTA | FV-002
A2: ⬅ Back to Master | Yellow = KEY FIELDS — update here, Master syncs automatically
B4: 🔗 KEY FIELDS — These automatically update the Master Sheet
B5: Client ID | C5: Last Consultation | D5: Progress | E5: Status | F5: Plan Type | G5: Plan Expiry | H5: Follow-up Freq (days) | I5: Client Tier | J5: Source
B6: FV-002 | C6: 46096 | D6: Very Good | E6: Active | F6: 6 Month Plan | G6: =IFERROR(G6+VLOOKUP(F6,Plan_Duration_Lookup,2,0),"Check Plan Type") -> Check Plan Type | H6: 21 | I6: 4 ⭐⭐⭐⭐ | J6: Instagram
B7: ⬆ Update yellow cells after each consultation. Plan Expiry calculates automatically from Plan Type + Start Date.
B9: 📌 PERSONAL DETAILS
B10: Full Name | C10: Rahul Mehta | E10: Age | F10: 28
B11: Client ID | C11: FV-002 | E11: Phone | F11: 9123456780
B12: City | C12: Surat | E12: Email
B13: Address | E13: Occupation
B14: Referred By | C14: — | E14: Emergency Contact
B16: 🎯 PLAN & GOALS
B17: Health Goal | C17: Muscle Gain | E17: Plan Type | F17: 6 Month Plan
B18: Plan Start Date | C18: 45992 | E18: Plan Duration | F18: 180 days (auto)
B19: Plan Expiry | C19: =IFERROR(C18+VLOOKUP(F6,Plan_Duration_Lookup,2,0),"—") -> 46172 | E19: Days Remaining | F19: =IFERROR(C19-TODAY(),"—") -> 23
B20: Medical Conditions | E20: Allergies / Avoid
B21: Activity Level | E21: Current Medications
B23: 📏 BODY STATS & BMI
B24: Height (cm) | C24: 175 | E24: Start Weight (kg) | F24: 65
B25: Current Weight (kg) | C25: 68.5 | E25: Target Weight (kg)
B26: BMI | C26: =IFERROR(ROUND(C25/((C24/100)^2),1),"—") -> 22.4 | E26: BMI Category | F26: =IFERROR(IF(C26<18.5,"⬇ Underweight",IF(C26<25,"✅ Normal",IF(C26<30,"⚠️ Overweight","🔴 Obese"))),"—") -> ✅ Normal
B27: Weight Change | C27: =IFERROR(C24-C25,"—") -> 106.5 | E27: % to Goal | F27: =IFERROR(TEXT((C24-C25)/(C24-F25),"0%"),"—") -> 61%
B29: 🤝 REFERRAL DETAILS
B30: Total Referrals Given | C30: 1 | E30: Client Tier | F30: 4 ⭐⭐⭐⭐
B31: # | C31: Client Name Referred | D31: Client ID | E31: Date Referred | F31: Notes
B32: 1 | C32: Anita Singh
B33: 2
B34: 3
B35: 4
B36: 5
B38: ✅ TASK ENGINE — Create, track & carry forward tasks
B39: Task Description | C39: Due Date | D39: Priority | E39: Status | F39: Period | G39: Completed On | H39: Notes
B40: Diet Review Call | C40: 46117 | D40: High | E40: Open | F40: This Week | H40: Review weight & adjust plan
B41: Send Updated Meal Plan | C41: 46107 | D41: High | E41: Open | F41: This Week | H41: Based on last consultation
B42: Check Supplement Stock | C42: 46110 | D42: Medium | E42: Open | F42: Next Week | H42: Ask if protein running low
B43: Monthly Progress Review | C43: 46112 | D43: High | E43: Open | F43: This Month | H43: Full BMI + energy check
B44: Payment / Renewal Reminder | C44: 46165 | D44: Medium | E44: Open | F44: Before Expiry | H44: Remind before plan expires
B45: Initial Consultation | C45: 45992 | D45: High | E45: Done ✅ | F45: Week 1 | G45: 2025-12-01 | H45: Onboarding complete
B46: First Diet Plan Delivery | C46: 45994 | D46: High | E46: Done ✅ | F46: Week 1 | G46: 2025-12-03 | H46: Sent via WhatsApp
...

Sheet FV-003
A1: 🌿 FITNESS VITNESS | SNEHA PATEL | FV-003
A2: ⬅ Back to Master | Yellow = KEY FIELDS — update here, Master syncs automatically
B4: 🔗 KEY FIELDS — These automatically update the Master Sheet
B5: Client ID | C5: Last Consultation | D5: Progress | E5: Status | F5: Plan Type | G5: Plan Expiry | H5: Follow-up Freq (days) | I5: Client Tier | J5: Source
B6: FV-003 | C6: 46063 | D6: Poor | E6: Active | F6: 3 Month Plan | G6: =IFERROR(G6+VLOOKUP(F6,Plan_Duration_Lookup,2,0),"Check Plan Type") -> Check Plan Type | H6: 7 | I6: 3 ⭐⭐⭐ | J6: Referral - Existing Client
B7: ⬆ Update yellow cells after each consultation. Plan Expiry calculates automatically from Plan Type + Start Date.
B9: 📌 PERSONAL DETAILS
B10: Full Name | C10: Sneha Patel | E10: Age | F10: 42
B11: Client ID | C11: FV-003 | E11: Phone | F11: 9988776655
B12: City | C12: Vapi | E12: Email
B13: Address | E13: Occupation
B14: Referred By | C14: Priya Sharma (FV-001) | E14: Emergency Contact
B16: 🎯 PLAN & GOALS
B17: Health Goal | C17: Diabetes Control | E17: Plan Type | F17: 3 Month Plan
B18: Plan Start Date | C18: 46054 | E18: Plan Duration | F18: 90 days (auto)
B19: Plan Expiry | C19: =IFERROR(C18+VLOOKUP(F6,Plan_Duration_Lookup,2,0),"—") -> 46144 | E19: Days Remaining | F19: =IFERROR(C19-TODAY(),"—") -> -5
B20: Medical Conditions | E20: Allergies / Avoid
B21: Activity Level | E21: Current Medications
B23: 📏 BODY STATS & BMI
B24: Height (cm) | C24: 158 | E24: Start Weight (kg) | F24: 85
B25: Current Weight (kg) | C25: 84.1 | E25: Target Weight (kg)
B26: BMI | C26: =IFERROR(ROUND(C25/((C24/100)^2),1),"—") -> 33.7 | E26: BMI Category | F26: =IFERROR(IF(C26<18.5,"⬇ Underweight",IF(C26<25,"✅ Normal",IF(C26<30,"⚠️ Overweight","🔴 Obese"))),"—") -> 🔴 Obese
B27: Weight Change | C27: =IFERROR(C24-C25,"—") -> 73.9 | E27: % to Goal | F27: =IFERROR(TEXT((C24-C25)/(C24-F25),"0%"),"—") -> 47%
B29: 🤝 REFERRAL DETAILS
B30: Total Referrals Given | C30: 0 | E30: Client Tier | F30: 3 ⭐⭐⭐
B31: # | C31: Client Name Referred | D31: Client ID | E31: Date Referred | F31: Notes
B32: 1
B33: 2
B34: 3
B35: 4
B36: 5
B38: ✅ TASK ENGINE — Create, track & carry forward tasks
B39: Task Description | C39: Due Date | D39: Priority | E39: Status | F39: Period | G39: Completed On | H39: Notes
B40: Diet Review Call | C40: 46070 | D40: High | E40: Open | F40: This Week | H40: Review weight & adjust plan
B41: Send Updated Meal Plan | C41: 46107 | D41: High | E41: Open | F41: This Week | H41: Based on last consultation
B42: Check Supplement Stock | C42: 46110 | D42: Medium | E42: Open | F42: Next Week | H42: Ask if protein running low
B43: Monthly Progress Review | C43: 46112 | D43: High | E43: Open | F43: This Month | H43: Full BMI + energy check
B44: Payment / Renewal Reminder | C44: 46137 | D44: Medium | E44: Open | F44: Before Expiry | H44: Remind before plan expires
B45: Initial Consultation | C45: 46054 | D45: High | E45: Done ✅ | F45: Week 1 | G45: 2026-02-01 | H45: Onboarding complete
B46: First Diet Plan Delivery | C46: 46056 | D46: High | E46: Done ✅ | F46: Week 1 | G46: 2026-02-03 | H46: Sent via WhatsApp
...

Sheet FV-004
A1: 🌿 FITNESS VITNESS | AMIT VERMA | FV-004
A2: ⬅ Back to Master | Yellow = KEY FIELDS — update here, Master syncs automatically
B4: 🔗 KEY FIELDS — These automatically update the Master Sheet
B5: Client ID | C5: Last Consultation | D5: Progress | E5: Status | F5: Plan Type | G5: Plan Expiry | H5: Follow-up Freq (days) | I5: Client Tier | J5: Source
B6: FV-004 | C6: 46073 | D6: Neutral | E6: Hold | F6: 1 Month Plan | G6: =IFERROR(G6+VLOOKUP(F6,Plan_Duration_Lookup,2,0),"Check Plan Type") -> Check Plan Type | H6: 30 | I6: 2 ⭐⭐ | J6: Online / Website
B7: ⬆ Update yellow cells after each consultation. Plan Expiry calculates automatically from Plan Type + Start Date.
B9: 📌 PERSONAL DETAILS
B10: Full Name | C10: Amit Verma | E10: Age | F10: 31
B11: Client ID | C11: FV-004 | E11: Phone | F11: 9871234560
B12: City | C12: Bharuch | E12: Email
B13: Address | E13: Occupation
B14: Referred By | C14: — | E14: Emergency Contact
B16: 🎯 PLAN & GOALS
B17: Health Goal | C17: Weight Loss | E17: Plan Type | F17: 1 Month Plan
B18: Plan Start Date | C18: 46073 | E18: Plan Duration | F18: 30 days (auto)
B19: Plan Expiry | C19: =IFERROR(C18+VLOOKUP(F6,Plan_Duration_Lookup,2,0),"—") -> 46103 | E19: Days Remaining | F19: =IFERROR(C19-TODAY(),"—") -> -46
B20: Medical Conditions | E20: Allergies / Avoid
B21: Activity Level | E21: Current Medications
B23: 📏 BODY STATS & BMI
B24: Height (cm) | C24: 170 | E24: Start Weight (kg) | F24: 90
B25: Current Weight (kg) | C25: 88.5 | E25: Target Weight (kg)
B26: BMI | C26: =IFERROR(ROUND(C25/((C24/100)^2),1),"—") -> 30.6 | E26: BMI Category | F26: =IFERROR(IF(C26<18.5,"⬇ Underweight",IF(C26<25,"✅ Normal",IF(C26<30,"⚠️ Overweight","🔴 Obese"))),"—") -> 🔴 Obese
B27: Weight Change | C27: =IFERROR(C24-C25,"—") -> 81.5 | E27: % to Goal | F27: =IFERROR(TEXT((C24-C25)/(C24-F25),"0%"),"—") -> 48%
B29: 🤝 REFERRAL DETAILS
B30: Total Referrals Given | C30: 0 | E30: Client Tier | F30: 2 ⭐⭐
B31: # | C31: Client Name Referred | D31: Client ID | E31: Date Referred | F31: Notes
B32: 1
B33: 2
B34: 3
B35: 4
B36: 5
B38: ✅ TASK ENGINE — Create, track & carry forward tasks
B39: Task Description | C39: Due Date | D39: Priority | E39: Status | F39: Period | G39: Completed On | H39: Notes
B40: Diet Review Call | C40: 46103 | D40: High | E40: Open | F40: This Week | H40: Review weight & adjust plan
B41: Send Updated Meal Plan | C41: 46107 | D41: High | E41: Open | F41: This Week | H41: Based on last consultation
B42: Check Supplement Stock | C42: 46110 | D42: Medium | E42: Open | F42: Next Week | H42: Ask if protein running low
B43: Monthly Progress Review | C43: 46112 | D43: High | E43: Open | F43: This Month | H43: Full BMI + energy check
B44: Payment / Renewal Reminder | C44: 46096 | D44: Medium | E44: Open | F44: Before Expiry | H44: Remind before plan expires
B45: Initial Consultation | C45: 46073 | D45: High | E45: Done ✅ | F45: Week 1 | G45: 2026-02-20 | H45: Onboarding complete
B46: First Diet Plan Delivery | C46: 46075 | D46: High | E46: Done ✅ | F46: Week 1 | G46: 2026-02-22 | H46: Sent via WhatsApp
...

Sheet FV-005
A1: 🌿 FITNESS VITNESS | KAVITA JOSHI | FV-005
A2: ⬅ Back to Master | Yellow = KEY FIELDS — update here, Master syncs automatically
B4: 🔗 KEY FIELDS — These automatically update the Master Sheet
B5: Client ID | C5: Last Consultation | D5: Progress | E5: Status | F5: Plan Type | G5: Plan Expiry | H5: Follow-up Freq (days) | I5: Client Tier | J5: Source
B6: FV-005 | C6: 46052 | D6: Very Poor | E6: Active | F6: 6 Month Plan | G6: =IFERROR(G6+VLOOKUP(F6,Plan_Duration_Lookup,2,0),"Check Plan Type") -> Check Plan Type | H6: 14 | I6: 5 ⭐⭐⭐⭐⭐ | J6: BNI
B7: ⬆ Update yellow cells after each consultation. Plan Expiry calculates automatically from Plan Type + Start Date.
B9: 📌 PERSONAL DETAILS
B10: Full Name | C10: Kavita Joshi | E10: Age | F10: 38
B11: Client ID | C11: FV-005 | E11: Phone | F11: 9765432109
B12: City | C12: Surat | E12: Email
B13: Address | E13: Occupation
B14: Referred By | C14: — | E14: Emergency Contact
B16: 🎯 PLAN & GOALS
B17: Health Goal | C17: Cholesterol Mgmt | E17: Plan Type | F17: 6 Month Plan
B18: Plan Start Date | C18: 46023 | E18: Plan Duration | F18: 180 days (auto)
B19: Plan Expiry | C19: =IFERROR(C18+VLOOKUP(F6,Plan_Duration_Lookup,2,0),"—") -> 46203 | E19: Days Remaining | F19: =IFERROR(C19-TODAY(),"—") -> 54
B20: Medical Conditions | E20: Allergies / Avoid
B21: Activity Level | E21: Current Medications
B23: 📏 BODY STATS & BMI
B24: Height (cm) | C24: 160 | E24: Start Weight (kg) | F24: 72
B25: Current Weight (kg) | C25: 73.2 | E25: Target Weight (kg)
B26: BMI | C26: =IFERROR(ROUND(C25/((C24/100)^2),1),"—") -> 28.6 | E26: BMI Category | F26: =IFERROR(IF(C26<18.5,"⬇ Underweight",IF(C26<25,"✅ Normal",IF(C26<30,"⚠️ Overweight","🔴 Obese"))),"—") -> ⚠️ Overweight
B27: Weight Change | C27: =IFERROR(C24-C25,"—") -> 86.8 | E27: % to Goal | F27: =IFERROR(TEXT((C24-C25)/(C24-F25),"0%"),"—") -> 54%
B29: 🤝 REFERRAL DETAILS
B30: Total Referrals Given | C30: 3 | E30: Client Tier | F30: 5 ⭐⭐⭐⭐⭐
B31: # | C31: Client Name Referred | D31: Client ID | E31: Date Referred | F31: Notes
B32: 1 | C32: Deepak Chauhan
B33: 2 | C33: Meena Kulkarni
B34: 3 | C34: Amit Verma
B35: 4
B36: 5
B38: ✅ TASK ENGINE — Create, track & carry forward tasks
B39: Task Description | C39: Due Date | D39: Priority | E39: Status | F39: Period | G39: Completed On | H39: Notes
B40: Diet Review Call | C40: 46066 | D40: High | E40: Open | F40: This Week | H40: Review weight & adjust plan
B41: Send Updated Meal Plan | C41: 46107 | D41: High | E41: Open | F41: This Week | H41: Based on last consultation
B42: Check Supplement Stock | C42: 46110 | D42: Medium | E42: Open | F42: Next Week | H42: Ask if protein running low
B43: Monthly Progress Review | C43: 46112 | D43: High | E43: Open | F43: This Month | H43: Full BMI + energy check
B44: Payment / Renewal Reminder | C44: 46196 | D44: Medium | E44: Open | F44: Before Expiry | H44: Remind before plan expires
B45: Initial Consultation | C45: 46023 | D45: High | E45: Done ✅ | F45: Week 1 | G45: 2026-01-01 | H45: Onboarding complete
B46: First Diet Plan Delivery | C46: 46025 | D46: High | E46: Done ✅ | F46: Week 1 | G46: 2026-01-03 | H46: Sent via WhatsApp
...

Sheet FV-006
A1: 🌿 FITNESS VITNESS | ROHIT DESAI | FV-006
A2: ⬅ Back to Master | Yellow = KEY FIELDS — update here, Master syncs automatically
B4: 🔗 KEY FIELDS — These automatically update the Master Sheet
B5: Client ID | C5: Last Consultation | D5: Progress | E5: Status | F5: Plan Type | G5: Plan Expiry | H5: Follow-up Freq (days) | I5: Client Tier | J5: Source
B6: FV-006 | C6: 46091 | D6: Good | E6: Active | F6: 3 Month Plan | G6: =IFERROR(G6+VLOOKUP(F6,Plan_Duration_Lookup,2,0),"Check Plan Type") -> Check Plan Type | H6: 21 | I6: 3 ⭐⭐⭐ | J6: Referral - Existing Client
B7: ⬆ Update yellow cells after each consultation. Plan Expiry calculates automatically from Plan Type + Start Date.
B9: 📌 PERSONAL DETAILS
B10: Full Name | C10: Rohit Desai | E10: Age | F10: 25
B11: Client ID | C11: FV-006 | E11: Phone | F11: 9654321098
B12: City | C12: Vapi | E12: Email
B13: Address | E13: Occupation
B14: Referred By | C14: Priya Sharma (FV-001) | E14: Emergency Contact
B16: 🎯 PLAN & GOALS
B17: Health Goal | C17: Muscle Gain | E17: Plan Type | F17: 3 Month Plan
B18: Plan Start Date | C18: 46054 | E18: Plan Duration | F18: 90 days (auto)
B19: Plan Expiry | C19: =IFERROR(C18+VLOOKUP(F6,Plan_Duration_Lookup,2,0),"—") -> 46144 | E19: Days Remaining | F19: =IFERROR(C19-TODAY(),"—") -> -5
B20: Medical Conditions | E20: Allergies / Avoid
B21: Activity Level | E21: Current Medications
B23: 📏 BODY STATS & BMI
B24: Height (cm) | C24: 172 | E24: Start Weight (kg) | F24: 60
B25: Current Weight (kg) | C25: 63 | E25: Target Weight (kg)
B26: BMI | C26: =IFERROR(ROUND(C25/((C24/100)^2),1),"—") -> 21.3 | E26: BMI Category | F26: =IFERROR(IF(C26<18.5,"⬇ Underweight",IF(C26<25,"✅ Normal",IF(C26<30,"⚠️ Overweight","🔴 Obese"))),"—") -> ✅ Normal
B27: Weight Change | C27: =IFERROR(C24-C25,"—") -> 109 | E27: % to Goal | F27: =IFERROR(TEXT((C24-C25)/(C24-F25),"0%"),"—") -> 63%
B29: 🤝 REFERRAL DETAILS
B30: Total Referrals Given | C30: 0 | E30: Client Tier | F30: 3 ⭐⭐⭐
B31: # | C31: Client Name Referred | D31: Client ID | E31: Date Referred | F31: Notes
B32: 1
B33: 2
B34: 3
B35: 4
B36: 5
B38: ✅ TASK ENGINE — Create, track & carry forward tasks
B39: Task Description | C39: Due Date | D39: Priority | E39: Status | F39: Period | G39: Completed On | H39: Notes
B40: Diet Review Call | C40: 46112 | D40: High | E40: Open | F40: This Week | H40: Review weight & adjust plan
B41: Send Updated Meal Plan | C41: 46107 | D41: High | E41: Open | F41: This Week | H41: Based on last consultation
B42: Check Supplement Stock | C42: 46110 | D42: Medium | E42: Open | F42: Next Week | H42: Ask if protein running low
B43: Monthly Progress Review | C43: 46112 | D43: High | E43: Open | F43: This Month | H43: Full BMI + energy check
B44: Payment / Renewal Reminder | C44: 46137 | D44: Medium | E44: Open | F44: Before Expiry | H44: Remind before plan expires
B45: Initial Consultation | C45: 46054 | D45: High | E45: Done ✅ | F45: Week 1 | G45: 2026-02-01 | H45: Onboarding complete
B46: First Diet Plan Delivery | C46: 46056 | D46: High | E46: Done ✅ | F46: Week 1 | G46: 2026-02-03 | H46: Sent via WhatsApp
...

Sheet FV-007
A1: 🌿 FITNESS VITNESS | MEENA KULKARNI | FV-007
A2: ⬅ Back to Master | Yellow = KEY FIELDS — update here, Master syncs automatically
B4: 🔗 KEY FIELDS — These automatically update the Master Sheet
B5: Client ID | C5: Last Consultation | D5: Progress | E5: Status | F5: Plan Type | G5: Plan Expiry | H5: Follow-up Freq (days) | I5: Client Tier | J5: Source
B6: FV-007 | C6: 46078 | D6: Poor | E6: Active | F6: 6 Month Plan | G6: =IFERROR(G6+VLOOKUP(F6,Plan_Duration_Lookup,2,0),"Check Plan Type") -> Check Plan Type | H6: 7 | I6: 2 ⭐⭐ | J6: Referral - Existing Client
B7: ⬆ Update yellow cells after each consultation. Plan Expiry calculates automatically from Plan Type + Start Date.
B9: 📌 PERSONAL DETAILS
B10: Full Name | C10: Meena Kulkarni | E10: Age | F10: 55
B11: Client ID | C11: FV-007 | E11: Phone | F11: 9543210987
B12: City | C12: Navsari | E12: Email
B13: Address | E13: Occupation
B14: Referred By | C14: Kavita Joshi (FV-005) | E14: Emergency Contact
B16: 🎯 PLAN & GOALS
B17: Health Goal | C17: Weight Loss | E17: Plan Type | F17: 6 Month Plan
B18: Plan Start Date | C18: 46032 | E18: Plan Duration | F18: 180 days (auto)
B19: Plan Expiry | C19: =IFERROR(C18+VLOOKUP(F6,Plan_Duration_Lookup,2,0),"—") -> 46212 | E19: Days Remaining | F19: =IFERROR(C19-TODAY(),"—") -> 63
B20: Medical Conditions | E20: Allergies / Avoid
B21: Activity Level | E21: Current Medications
B23: 📏 BODY STATS & BMI
B24: Height (cm) | C24: 155 | E24: Start Weight (kg) | F24: 92
B25: Current Weight (kg) | C25: 89.5 | E25: Target Weight (kg)
B26: BMI | C26: =IFERROR(ROUND(C25/((C24/100)^2),1),"—") -> 37.3 | E26: BMI Category | F26: =IFERROR(IF(C26<18.5,"⬇ Underweight",IF(C26<25,"✅ Normal",IF(C26<30,"⚠️ Overweight","🔴 Obese"))),"—") -> 🔴 Obese
B27: Weight Change | C27: =IFERROR(C24-C25,"—") -> 65.5 | E27: % to Goal | F27: =IFERROR(TEXT((C24-C25)/(C24-F25),"0%"),"—") -> 42%
B29: 🤝 REFERRAL DETAILS
B30: Total Referrals Given | C30: 0 | E30: Client Tier | F30: 2 ⭐⭐
B31: # | C31: Client Name Referred | D31: Client ID | E31: Date Referred | F31: Notes
B32: 1
B33: 2
B34: 3
B35: 4
B36: 5
B38: ✅ TASK ENGINE — Create, track & carry forward tasks
B39: Task Description | C39: Due Date | D39: Priority | E39: Status | F39: Period | G39: Completed On | H39: Notes
B40: Diet Review Call | C40: 46085 | D40: High | E40: Open | F40: This Week | H40: Review weight & adjust plan
B41: Send Updated Meal Plan | C41: 46107 | D41: High | E41: Open | F41: This Week | H41: Based on last consultation
B42: Check Supplement Stock | C42: 46110 | D42: Medium | E42: Open | F42: Next Week | H42: Ask if protein running low
B43: Monthly Progress Review | C43: 46112 | D43: High | E43: Open | F43: This Month | H43: Full BMI + energy check
B44: Payment / Renewal Reminder | C44: 46205 | D44: Medium | E44: Open | F44: Before Expiry | H44: Remind before plan expires
B45: Initial Consultation | C45: 46032 | D45: High | E45: Done ✅ | F45: Week 1 | G45: 2026-01-10 | H45: Onboarding complete
B46: First Diet Plan Delivery | C46: 46034 | D46: High | E46: Done ✅ | F46: Week 1 | G46: 2026-01-12 | H46: Sent via WhatsApp
...

Sheet FV-008
A1: 🌿 FITNESS VITNESS | SURESH NAIR | FV-008
A2: ⬅ Back to Master | Yellow = KEY FIELDS — update here, Master syncs automatically
B4: 🔗 KEY FIELDS — These automatically update the Master Sheet
B5: Client ID | C5: Last Consultation | D5: Progress | E5: Status | F5: Plan Type | G5: Plan Expiry | H5: Follow-up Freq (days) | I5: Client Tier | J5: Source
B6: FV-008 | C6: 46099 | D6: Good | E6: Hold | F6: 1 Month Plan | G6: =IFERROR(G6+VLOOKUP(F6,Plan_Duration_Lookup,2,0),"Check Plan Type") -> Check Plan Type | H6: 30 | I6: 3 ⭐⭐⭐ | J6: Referral - Existing Client
B7: ⬆ Update yellow cells after each consultation. Plan Expiry calculates automatically from Plan Type + Start Date.
B9: 📌 PERSONAL DETAILS
B10: Full Name | C10: Suresh Nair | E10: Age | F10: 46
B11: Client ID | C11: FV-008 | E11: Phone | F11: 9432109876
B12: City | C12: Vapi | E12: Email
B13: Address | E13: Occupation
B14: Referred By | C14: Priya Sharma (FV-001) | E14: Emergency Contact
B16: 🎯 PLAN & GOALS
B17: Health Goal | C17: General Wellness | E17: Plan Type | F17: 1 Month Plan
B18: Plan Start Date | C18: 46082 | E18: Plan Duration | F18: 30 days (auto)
B19: Plan Expiry | C19: =IFERROR(C18+VLOOKUP(F6,Plan_Duration_Lookup,2,0),"—") -> 46112 | E19: Days Remaining | F19: =IFERROR(C19-TODAY(),"—") -> -37
B20: Medical Conditions | E20: Allergies / Avoid
B21: Activity Level | E21: Current Medications
B23: 📏 BODY STATS & BMI
B24: Height (cm) | C24: 168 | E24: Start Weight (kg) | F24: 80
B25: Current Weight (kg) | C25: 79.2 | E25: Target Weight (kg)
B26: BMI | C26: =IFERROR(ROUND(C25/((C24/100)^2),1),"—") -> 28.1 | E26: BMI Category | F26: =IFERROR(IF(C26<18.5,"⬇ Underweight",IF(C26<25,"✅ Normal",IF(C26<30,"⚠️ Overweight","🔴 Obese"))),"—") -> ⚠️ Overweight
B27: Weight Change | C27: =IFERROR(C24-C25,"—") -> 88.8 | E27: % to Goal | F27: =IFERROR(TEXT((C24-C25)/(C24-F25),"0%"),"—") -> 53%
B29: 🤝 REFERRAL DETAILS
B30: Total Referrals Given | C30: 0 | E30: Client Tier | F30: 3 ⭐⭐⭐
B31: # | C31: Client Name Referred | D31: Client ID | E31: Date Referred | F31: Notes
B32: 1
B33: 2
B34: 3
B35: 4
B36: 5
B38: ✅ TASK ENGINE — Create, track & carry forward tasks
B39: Task Description | C39: Due Date | D39: Priority | E39: Status | F39: Period | G39: Completed On | H39: Notes
B40: Diet Review Call | C40: 46129 | D40: High | E40: Open | F40: This Week | H40: Review weight & adjust plan
B41: Send Updated Meal Plan | C41: 46107 | D41: High | E41: Open | F41: This Week | H41: Based on last consultation
B42: Check Supplement Stock | C42: 46110 | D42: Medium | E42: Open | F42: Next Week | H42: Ask if protein running low
B43: Monthly Progress Review | C43: 46112 | D43: High | E43: Open | F43: This Month | H43: Full BMI + energy check
B44: Payment / Renewal Reminder | C44: 46105 | D44: Medium | E44: Open | F44: Before Expiry | H44: Remind before plan expires
B45: Initial Consultation | C45: 46082 | D45: High | E45: Done ✅ | F45: Week 1 | G45: 2026-03-01 | H45: Onboarding complete
B46: First Diet Plan Delivery | C46: 46084 | D46: High | E46: Done ✅ | F46: Week 1 | G46: 2026-03-03 | H46: Sent via WhatsApp
...

Sheet FV-009
A1: 🌿 FITNESS VITNESS | ANITA SINGH | FV-009
A2: ⬅ Back to Master | Yellow = KEY FIELDS — update here, Master syncs automatically
B4: 🔗 KEY FIELDS — These automatically update the Master Sheet
B5: Client ID | C5: Last Consultation | D5: Progress | E5: Status | F5: Plan Type | G5: Plan Expiry | H5: Follow-up Freq (days) | I5: Client Tier | J5: Source
B6: FV-009 | C6: 46101 | D6: Very Good | E6: Active | F6: 3 Month Plan | G6: =IFERROR(G6+VLOOKUP(F6,Plan_Duration_Lookup,2,0),"Check Plan Type") -> Check Plan Type | H6: 14 | I6: 4 ⭐⭐⭐⭐ | J6: Referral - Existing Client
B7: ⬆ Update yellow cells after each consultation. Plan Expiry calculates automatically from Plan Type + Start Date.
B9: 📌 PERSONAL DETAILS
B10: Full Name | C10: Anita Singh | E10: Age | F10: 29
B11: Client ID | C11: FV-009 | E11: Phone | F11: 9321098765
B12: City | C12: Valsad | E12: Email
B13: Address | E13: Occupation
B14: Referred By | C14: Rahul Mehta (FV-002) | E14: Emergency Contact
B16: 🎯 PLAN & GOALS
B17: Health Goal | C17: Weight Loss | E17: Plan Type | F17: 3 Month Plan
B18: Plan Start Date | C18: 46068 | E18: Plan Duration | F18: 90 days (auto)
B19: Plan Expiry | C19: =IFERROR(C18+VLOOKUP(F6,Plan_Duration_Lookup,2,0),"—") -> 46158 | E19: Days Remaining | F19: =IFERROR(C19-TODAY(),"—") -> 9
B20: Medical Conditions | E20: Allergies / Avoid
B21: Activity Level | E21: Current Medications
B23: 📏 BODY STATS & BMI
B24: Height (cm) | C24: 163 | E24: Start Weight (kg) | F24: 68
B25: Current Weight (kg) | C25: 65.1 | E25: Target Weight (kg)
B26: BMI | C26: =IFERROR(ROUND(C25/((C24/100)^2),1),"—") -> 24.5 | E26: BMI Category | F26: =IFERROR(IF(C26<18.5,"⬇ Underweight",IF(C26<25,"✅ Normal",IF(C26<30,"⚠️ Overweight","🔴 Obese"))),"—") -> ✅ Normal
B27: Weight Change | C27: =IFERROR(C24-C25,"—") -> 97.9 | E27: % to Goal | F27: =IFERROR(TEXT((C24-C25)/(C24-F25),"0%"),"—") -> 60%
B29: 🤝 REFERRAL DETAILS
B30: Total Referrals Given | C30: 0 | E30: Client Tier | F30: 4 ⭐⭐⭐⭐
B31: # | C31: Client Name Referred | D31: Client ID | E31: Date Referred | F31: Notes
B32: 1
B33: 2
B34: 3
B35: 4
B36: 5
B38: ✅ TASK ENGINE — Create, track & carry forward tasks
B39: Task Description | C39: Due Date | D39: Priority | E39: Status | F39: Period | G39: Completed On | H39: Notes
B40: Diet Review Call | C40: 46115 | D40: High | E40: Open | F40: This Week | H40: Review weight & adjust plan
B41: Send Updated Meal Plan | C41: 46107 | D41: High | E41: Open | F41: This Week | H41: Based on last consultation
B42: Check Supplement Stock | C42: 46110 | D42: Medium | E42: Open | F42: Next Week | H42: Ask if protein running low
B43: Monthly Progress Review | C43: 46112 | D43: High | E43: Open | F43: This Month | H43: Full BMI + energy check
B44: Payment / Renewal Reminder | C44: 46151 | D44: Medium | E44: Open | F44: Before Expiry | H44: Remind before plan expires
B45: Initial Consultation | C45: 46068 | D45: High | E45: Done ✅ | F45: Week 1 | G45: 2026-02-15 | H45: Onboarding complete
B46: First Diet Plan Delivery | C46: 46070 | D46: High | E46: Done ✅ | F46: Week 1 | G46: 2026-02-17 | H46: Sent via WhatsApp
...

Sheet FV-010
A1: 🌿 FITNESS VITNESS | DEEPAK CHAUHAN | FV-010
A2: ⬅ Back to Master | Yellow = KEY FIELDS — update here, Master syncs automatically
B4: 🔗 KEY FIELDS — These automatically update the Master Sheet
B5: Client ID | C5: Last Consultation | D5: Progress | E5: Status | F5: Plan Type | G5: Plan Expiry | H5: Follow-up Freq (days) | I5: Client Tier | J5: Source
B6: FV-010 | C6: 46086 | D6: Neutral | E6: Active | F6: 6 Month Plan | G6: =IFERROR(G6+VLOOKUP(F6,Plan_Duration_Lookup,2,0),"Check Plan Type") -> Check Plan Type | H6: 21 | I6: 2 ⭐⭐ | J6: Referral - Existing Client
B7: ⬆ Update yellow cells after each consultation. Plan Expiry calculates automatically from Plan Type + Start Date.
B9: 📌 PERSONAL DETAILS
B10: Full Name | C10: Deepak Chauhan | E10: Age | F10: 33
B11: Client ID | C11: FV-010 | E11: Phone | F11: 9210987654
B12: City | C12: Vapi | E12: Email
B13: Address | E13: Occupation
B14: Referred By | C14: Kavita Joshi (FV-005) | E14: Emergency Contact
B16: 🎯 PLAN & GOALS
B17: Health Goal | C17: Muscle Gain | E17: Plan Type | F17: 6 Month Plan
B18: Plan Start Date | C18: 46023 | E18: Plan Duration | F18: 180 days (auto)
B19: Plan Expiry | C19: =IFERROR(C18+VLOOKUP(F6,Plan_Duration_Lookup,2,0),"—") -> 46203 | E19: Days Remaining | F19: =IFERROR(C19-TODAY(),"—") -> 54
B20: Medical Conditions | E20: Allergies / Avoid
B21: Activity Level | E21: Current Medications
B23: 📏 BODY STATS & BMI
B24: Height (cm) | C24: 174 | E24: Start Weight (kg) | F24: 70
B25: Current Weight (kg) | C25: 72.8 | E25: Target Weight (kg)
B26: BMI | C26: =IFERROR(ROUND(C25/((C24/100)^2),1),"—") -> 24 | E26: BMI Category | F26: =IFERROR(IF(C26<18.5,"⬇ Underweight",IF(C26<25,"✅ Normal",IF(C26<30,"⚠️ Overweight","🔴 Obese"))),"—") -> ✅ Normal
B27: Weight Change | C27: =IFERROR(C24-C25,"—") -> 101.2 | E27: % to Goal | F27: =IFERROR(TEXT((C24-C25)/(C24-F25),"0%"),"—") -> 58%
B29: 🤝 REFERRAL DETAILS
B30: Total Referrals Given | C30: 0 | E30: Client Tier | F30: 2 ⭐⭐
B31: # | C31: Client Name Referred | D31: Client ID | E31: Date Referred | F31: Notes
B32: 1
B33: 2
B34: 3
B35: 4
B36: 5
B38: ✅ TASK ENGINE — Create, track & carry forward tasks
B39: Task Description | C39: Due Date | D39: Priority | E39: Status | F39: Period | G39: Completed On | H39: Notes
B40: Diet Review Call | C40: 46107 | D40: High | E40: Open | F40: This Week | H40: Review weight & adjust plan
B41: Send Updated Meal Plan | C41: 46107 | D41: High | E41: Open | F41: This Week | H41: Based on last consultation
B42: Check Supplement Stock | C42: 46110 | D42: Medium | E42: Open | F42: Next Week | H42: Ask if protein running low
B43: Monthly Progress Review | C43: 46112 | D43: High | E43: Open | F43: This Month | H43: Full BMI + energy check
B44: Payment / Renewal Reminder | C44: 46196 | D44: Medium | E44: Open | F44: Before Expiry | H44: Remind before plan expires
B45: Initial Consultation | C45: 46023 | D45: High | E45: Done ✅ | F45: Week 1 | G45: 2026-01-01 | H45: Onboarding complete
B46: First Diet Plan Delivery | C46: 46025 | D46: High | E46: Done ✅ | F46: Week 1 | G46: 2026-01-03 | H46: Sent via WhatsApp
...

Sheet 📄 TEMPLATE
A1: 📄 TEMPLATE — Right-click → Move or Copy → rename to new Client ID (e.g. FV-011). Never edit this sheet directly.
A2: ⬅ Back to Master | Yellow = KEY FIELDS — update here, Master syncs automatically
B4: 🔗 KEY FIELDS — These automatically update the Master Sheet
B5: Client ID | C5: Last Consultation | D5: Progress | E5: Status | F5: Plan Type | G5: Plan Expiry | H5: Follow-up Freq (days) | I5: Client Tier | J5: Source
B6: FV-000 | C6: 46023 | D6: Neutral | E6: Active | F6: 3 Month Plan | G6: =IFERROR(G6+VLOOKUP(F6,Plan_Duration_Lookup,2,0),"Check Plan Type") -> Check Plan Type | H6: 14 | I6: 3 ⭐⭐⭐
B7: ⬆ Update yellow cells after each consultation. Plan Expiry calculates automatically from Plan Type + Start Date.
B9: 📌 PERSONAL DETAILS
B10: Full Name | C10: NEW CLIENT TEMPLATE | E10: Age
B11: Client ID | C11: FV-000 | E11: Phone
B12: City | E12: Email
B13: Address | E13: Occupation
B14: Referred By | C14: — | E14: Emergency Contact
B16: 🎯 PLAN & GOALS
B17: Health Goal | E17: Plan Type | F17: 3 Month Plan
B18: Plan Start Date | C18: 46023 | E18: Plan Duration | F18: 90 days (auto)
B19: Plan Expiry | C19: =IFERROR(C18+VLOOKUP(F6,Plan_Duration_Lookup,2,0),"—") -> 46113 | E19: Days Remaining | F19: =IFERROR(C19-TODAY(),"—") -> -36
B20: Medical Conditions | E20: Allergies / Avoid
B21: Activity Level | E21: Current Medications
B23: 📏 BODY STATS & BMI
B24: Height (cm) | C24: 0 | E24: Start Weight (kg) | F24: 0
B25: Current Weight (kg) | C25: 0 | E25: Target Weight (kg)
B26: BMI | C26: =IFERROR(ROUND(C25/((C24/100)^2),1),"—") -> — | E26: BMI Category | F26: =IFERROR(IF(C26<18.5,"⬇ Underweight",IF(C26<25,"✅ Normal",IF(C26<30,"⚠️ Overweight","🔴 Obese"))),"—") -> 🔴 Obese
B27: Weight Change | C27: =IFERROR(C24-C25,"—") -> 0 | E27: % to Goal | F27: =IFERROR(TEXT((C24-C25)/(C24-F25),"0%"),"—") -> —
B29: 🤝 REFERRAL DETAILS
B30: Total Referrals Given | C30: 0 | E30: Client Tier | F30: 3 ⭐⭐⭐
B31: # | C31: Client Name Referred | D31: Client ID | E31: Date Referred | F31: Notes
B32: 1
B33: 2
B34: 3
B35: 4
B36: 5
B38: ✅ TASK ENGINE — Create, track & carry forward tasks
B39: Task Description | C39: Due Date | D39: Priority | E39: Status | F39: Period | G39: Completed On | H39: Notes
B40: Diet Review Call | C40: 46037 | D40: High | E40: Open | F40: This Week | H40: Review weight & adjust plan
B41: Send Updated Meal Plan | C41: 46107 | D41: High | E41: Open | F41: This Week | H41: Based on last consultation
B42: Check Supplement Stock | C42: 46110 | D42: Medium | E42: Open | F42: Next Week | H42: Ask if protein running low
B43: Monthly Progress Review | C43: 46112 | D43: High | E43: Open | F43: This Month | H43: Full BMI + energy check
B44: Payment / Renewal Reminder | C44: 46106 | D44: Medium | E44: Open | F44: Before Expiry | H44: Remind before plan expires
B45: Initial Consultation | C45: 46023 | D45: High | E45: Done ✅ | F45: Week 1 | G45: 2026-01-01 | H45: Onboarding complete
B46: First Diet Plan Delivery | C46: 46025 | D46: High | E46: Done ✅ | F46: Week 1 | G46: 2026-01-03 | H46: Sent via WhatsApp
...
